from time import time
from contextlib import redirect_stdout
import io
import inspect
import sys
import traceback
from datetime import datetime

class decorator_4:
    dic_time = {}

    def __init__(self, func):
        self.function = func
        self.count = 0

    def __call__(self, *args, **kwargs):
        try:
            res = self.function(*args, **kwargs)
            return res
        except Exception as e:
            tb = sys.exc_info()[-1]
            stk = traceback.extract_tb(tb)
            with open('log_file.txt', 'a+') as f:
                f.write(f'{datetime.strftime(datetime.now(), f"%y-%m-%d %H:%M:%S: ")}function {stk[2][2]} {e} \n')
            print(f'Error in calling {stk[2][2]} written in the log file.')
        # why do you return None here outside the except block but Return res inside the try block
        return None